<?xml version="1.0"?>
<robot name="my_robot">
    <link name="base_link">
        <visual>
            <geometry>
                <box size="0.6 0.4 0.2"/>
            </geometry>
            <material name="green">
                <color rgba="0 1 0 1"/>
            </material>
            <origin xyz="0 0 0" rpy="0 0 0"/>
        </visual>
    </link>

    <joint name="first_joint" type="revolute">
        <parent link="base_link"/>
        <child link="first_link"/>
        <origin xyz="0 0 0.1" rpy="0 0 0"/>
        <axis xyz="0 0 1"/>
        <limit effort="300" velocity="2.0" lower="-6" upper="6"/>
    </joint>

    <link name="first_link">
        <visual>
            <geometry>
                <cylinder length="0.5" radius="0.08"/>
            </geometry>
            <material name="red">
                <color rgba="1 0 0 1"/>
            </material>
            <origin xyz="0 0 0.2" rpy="0 0 0"/>
        </visual>
    </link>

    <joint name="second_joint" type="revolute">
        <parent link="first_link"/>
        <child link="second_link"/>
        <origin xyz="0 0 0.5" rpy="0 0 0"/>
        <axis xyz="0 0 1"/>
        <limit effort="300" velocity="2.0" lower="-1.57" upper="1.57"/>
    </joint>

    <link name="second_link">
        <visual>
            <geometry>
                <cylinder length="0.5" radius="0.08"/>
            </geometry>
            <material name="red"/>
            <origin xyz="0.2 0 0.1" rpy="0 1.3 0"/>
        </visual>
    </link>

    <joint name="third_joint" type="revolute">
        <parent link="second_link"/>
        <child link="third_link"/>
        <origin xyz="0.5 0 0.17" rpy="1.57 0 0"/>
        <axis xyz="0 0 1"/>
        <limit effort="300" velocity="2.0" lower="-0.300" upper="0.700"/>
    </joint>

    <link name="third_link">
        <visual>
            <geometry>
                <cylinder length="0.5" radius="0.08"/>
            </geometry>
            <material name="red"/>
            <origin xyz="0.20 -0.10 0" rpy="-1.57 0 1.1"/>
        </visual>
    </link>


    <link name="left_gripper">
        <visual>
            <geometry>
                <mesh filename="package://urdf_tutorial/meshes/l_finger.dae"/>
            </geometry>
            <material name ="green"/>
            <origin xyz="0 0 0" rpy="0 0 0"/>
        </visual>
    </link>

    <joint name="gripper_joint" type="fixed">
        <parent link="third_link"/>
        <child link="left_gripper"/>
        <origin xyz="0.46 -0.221 0" rpy="0 0 -0.4"/>
    </joint>

    <link name="right_gripper">
        <visual>
            <geometry>
                <mesh filename="package://urdf_tutorial/meshes/l_finger.dae"/>
            </geometry>
            <origin xyz="0 0 0" rpy="0 0 0"/>
        </visual>
    </link>

    <joint name="r_gripper_joint" type="fixed">
        <parent link="third_link"/>
        <child link="right_gripper"/>
        <origin xyz="0.46 -0.221 0" rpy="-3.1415 0 -0.4"/>
    </joint>



</robot>



